Workbook

Sheet Metadata
A1: Expedition: | B1: Saba bank pregnant tiger shark 2021
A2: Dates: | B2: 01/08/2021 - 06/08/2021
A3: Location: | B3: Saba_bank
A5: Participants: | E5: Sites:
A6: Giancarlo Nunes | B6: FPNA | E6: moonfish_reef
A7: Tadzio Bervoets | B7: DCNA | E7: poison_bank
A8: Roxanne-Liana Francisca | B8: STINAPA
A9: Paulo Bertuol | B9: STINAPA | E9: Shark names:
A10: Guido Leurs | B10: Uni Groningen | E10: Male | F10: Female
A11: Arjan de Groene | B11: WWF-NL | E11: Maestro Angelo | F11: Chloe Brigitte
A12: Ayumi Kuramae | B12: SCF | E12: Cornelis Sprado | F12: Oma Brigitte
A13: Dahlia Hassell | B13: DCNA | E13: Castor Sprado | F13: Koekie
A14: Marijn van der Laan | B14: SCF | E14: Ijzer | F14: Kinky
A15: Francois Mille | B15: STENAPA | E15: Aldo | F15: Felix Bamborough
A16: Marit Pistor | B16: STENAPA | E16: Oom Neef | F16: Nuka
A17: Melanie Meijer | B17: NFSXM
A18: Leslie Hickerson | B18: NFSXM
A19: Daniel Norwood | B19: SXM Divers (photographer)
A20: Brooke Anderson | B20: Arizona State University
A21: Sami Kattan | B21: Beneath the Waves (videographer)
A22: Walter Hynds | B22: SCF
A23: Tom Brokke | B23: SCF
A24: Zachary Johnson | B24: NA.
A25: Emily Malsack | B25: Sea&Learn
A27: Expedition: | B27: RTL TV Expedition 2022
A28: Dates: | B28: 25/11/2022 - 29/11/2022
A29: Location: | B29: St Maarten
A31: Participants: | D31: Sites:
A32: Walter Hynds | B32: SCF | D32: SXM
A33: Marijn van der Laan | B33: SCF
A34: Kai Wulf | B34: SCF
A35: Tom Brokke | B35: SCF
A36: Ayumi Kuramae | B36: SCF
A37: Erwin Winter | B37: WMR
A38: Jeroen Ham | B38: WMR
A39: Francesco Pelizza | B39: WMR
A40: Leslie Hickerson | B40: NFSXM
A41: Delhon Hewitt | B41: NFSXM
A42: Chrsital | B42: NFSXM
A43: Zakiya | B43: NFSXM
...

Sheet Lookup
A1: Bait: | D1: Data gathered: | G1: Species codes:
A2: S = Snapper | D2: Hook | E2: set number | G2: CRS | H2: Caribbean reef shark
A3: BS = Blackfin snapper | D3: result | E3: BU = bait untouched; BB = bait bitten; BG = bait gone; SH = shark (plus shark number); OTH = other (see comments) | G3: TS | H3: Tiger shark
A4: YS = Yellow eye snapper | D4: shark ID | E4: shark number in sequence | G4: NS | H4: Nurse shark
A5: VS = Vermillion snapper | D5: Bait | E5: BH = bonito head, BM = bonito mid, BT = bonito tail; BF = whole bonito fish, CRS = caribbean reef shark; UNK = unknown
A6: JB = Japanese bait | D6: TL | E6: total length; length from snout to upper lobe of tail fin
A7: BT = Bonito tail | D7: FL | E7: fork length; length from snout to fork in tail
A8: BART = Barracuda tail | D8: PCL | E8: precaudal length; length from snout to caudal pit
A9: BM = Bonito mid | D9: girth | E9: circumference of shark between pectoral and dorsal fin
A10: BAM = Barracuda mid | D10: blood | E10: indicated with sample number
A11: BAH = Barracuda head | D11: Ultrasound | E11: indicated with ultrasound number
A12: WG = White grunt | D12: PIT | E12: internal chip
A13: C = Coney | D13: Floy | E13: orange CSC tags
A14: RBP = Red band parrotfish | D14: Sattelite tag | E14: serial and PITT number
A15: P = Porgy | D15: Cloacal swab | E15: 0 = no cloacal swab; 1 = cloacal swab performed
A16: CW = cotton wick | D16: DNA | E16: taken in form of fin clip; 0 = no DNA taken, 1 = DNA taken
... A18: CG = Ceasar grunt | D18: Stage | E18: Adult = adult, SUB = sub-adult, Juvenile = juvenile
A19: AJ = Amber jack
A20: AJM = Amber jack mid | D20: Data gathered:
A21: AJH = Amber jack head | D21: Method | E21: RR = rod & reel; HL = handline
A22: BW = Bonito whole | D22: Hook | E22: rod/line number
A23: CO_live = Coney alive | D23: result | E23: BU = bait untouched; BB = bait bitten; BG = bait gone; S = shark (plus shark number); OTH = other (see comments)
A24: ESCT = Escolar tail | D24: shark ID | E24: shark number in sequence
A25: NST = Nurse shark tail | D25: Bait | E25: BH = bonito head, BM = bonito mid, BT = bonito tail; CRS = caribbean reef shark; UNK = unknown; OB = Whole bonito
A26: NS = Nurse shark | D26: TL | E26: total length; length from snout to upper lobe of tail fin
A27: NSH = Nurse shark head | D27: FL | E27: fork length; length from snout to fork in tail
A28: RSM = Reef shark mid | D28: PCL | E28: precaudal length; length from snout to caudal pit
A29: ESCH = Escolar head | D29: girth | E29: circumference of shark between pectoral and dorsal fin
A30: LF = Lion fish | D30: blood | E30: indicated with sample number
A31: BH = Bonito head | D31: Ultrasound | E31: indicated with ultrasound number
A32: BAT = Barracuda Tail | D32: PIT | E32: internal chip
... A35: BRT = Blue Runner Tail | D35: Cloacal swab | E35: 0 = no cloacal swab; 1 = cloacal swab performed
D36: DNA | E36: taken in form of fin clip; 0 = no DNA taken, 1 = DNA taken
D37: Acoustic | E37: ID number of the acoustic tag
D38: Serial | E38: Serial number of the Acoustic tag
D41: Data gathered:
D42: Method | E42: RR = rod & reel; HL = handline; DLb = Drumline bottomset; DL = Drumline regular
D43: Hook | E43: rod/line number
D44: result | E44: BU = bait untouched; BB = bait bitten; BG = bait gone; S = shark (plus shark number); OTH = other (see comments)
D45: shark ID | E45: shark number in sequence
...

Sheet Capture data
A1: Project | B1: Year | C1: Month | D1: Day | E1: shark_id | F1: name | G1: method | H1: set | I1: check | J1: waypoint | K1: latitude | L1: longitude | M1: depth_(m) | N1: location | O1: site | P1: time | Q1: bait | R1: species_sn | S1: species_cn | T1: sex | U1: TL_(cm) | V1: FL_(cm) | W1: PCL_(cm) | X1: girth_(cm) | Y1: DNA | Z1: blood | AA1: PIT | AB1: FLOY | AC1: Acoustic_ID | AD1: Vemco_Serial | AE1: SAT_serial | AF1: satellite_PITT | AG1: ultrasound | AH1: cloacal_swab | AI1: muscle_sample_nr | AJ1: recapture | AK1: comments
A2: SoS | B2: 2014 | C2: October | D2: 23 | E2: UN | F2: Adam | G2: Rod-Hook | K2: 17.64614 | L2: -63.26499 | M2: 28 | N2: Saba Island | O2: Shark Shoal | P2: 0.54166667 | Q2: Jap bait | R2: Carcharhinus perezii | S2: Caribbean Reef Shark | T2: M | U2: 150 | V2: NA | W2: NA | X2: NA | Y2: 0 | Z2: 0 | AA2: NA | AB2: NA | AC2: 590 | AD2: NA | AE2: NA | AF2: NA | AG2: NA | AH2: 0 | AI2: NA | AJ2: 0
A3: SoS | B3: 2014 | C3: October | D3: 23 | E3: UN | F3: Barbara | G3: Rod-Hook | K3: 17.64614 | L3: -63.26499 | M3: 28 | N3: Saba Island | O3: Shark Shoal | P3: 0.56944444 | Q3: Jap bait | R3: Carcharhinus perezii | S3: Caribbean Reef Shark | T3: F | U3: 184 | V3: NA | W3: NA | X3: NA | Y3: 0 | Z3: 0 | AA3: NA | AB3: NA | AC3: 591 | AD3: NA | AE3: NA | AF3: NA | AG3: NA | AH3: 0 | AI3: NA | AJ3: 0
A4: SoS | B4: 2014 | C4: October | D4: 24 | E4: UN | F4: Chelsea | G4: Rod-Hook | K4: 17.63205 | L4: -63.2743 | M4: 28 | N4: Saba Island | O4: Third Encounter | P4: 0.39583333 | Q4: Jap bait | R4: Carcharhinus perezii | S4: Caribbean Reef Shark | T4: F | U4: 180 | V4: NA | W4: NA | X4: NA | Y4: 0 | Z4: 0 | AA4: NA | AB4: NA | AC4: 592 | AD4: NA | AE4: NA | AF4: NA | AG4: NA | AH4: 0 | AI4: NA | AJ4: 0
A5: SoS | B5: 2014 | C5: October | D5: 24 | E5: UN | F5: Dahlia | G5: Rod-Hook | K5: 17.6328 | L5: -63.27462 | M5: 29 | N5: Saba Island | O5: Twilight Zone | P5: 0.52430556 | Q5: Black Jack | R5: Carcharhinus perezii | S5: Caribbean Reef Shark | T5: F | U5: 131 | V5: NA | W5: NA | X5: NA | Y5: 0 | Z5: 0 | AA5: NA | AB5: NA | AC5: 593 | AD5: NA | AE5: NA | AF5: NA | AG5: NA | AH5: 0 | AI5: NA | AJ5: 0
A6: SoS | B6: 2014 | C6: October | D6: 24 | E6: UN | F6: Eric | G6: Rod-Hook | K6: 17.6328 | L6: -63.27462 | M6: 29 | N6: Saba Island | O6: Twilight Zone | P6: 0.53472222 | Q6: Black Jack | R6: Carcharhinus perezii | S6: Caribbean Reef Shark | T6: M | U6: 115 | V6: NA | W6: NA | X6: NA | Y6: 0 | Z6: 0 | AA6: NA | AB6: NA | AC6: 594 | AD6: NA | AE6: NA | AF6: NA | AG6: NA | AH6: 0 | AI6: NA | AJ6: 0
A7: SoS | B7: 2014 | C7: October | D7: 24 | E7: UN | F7: Fifi | G7: Rod-Hook | K7: 17.6328 | L7: -63.27462 | M7: 29 | N7: Saba Island | O7: Twilight Zone | P7: 0.57291667 | Q7: Black Jack | R7: Carcharhinus perezii | S7: Caribbean Reef Shark | T7: F | U7: 125 | V7: NA | W7: NA | X7: NA | Y7: 0 | Z7: 0 | AA7: NA | AB7: NA | AC7: 595 | AD7: NA | AE7: NA | AF7: NA | AG7: NA | AH7: 0 | AI7: NA | AJ7: 0
A8: SoS | B8: 2014 | C8: October | D8: 25 | E8: UN | F8: Gonzalo | G8: Longline-monofyl | K8: 17.64888 | L8: -63.2311 | M8: 16 | N8: Saba Island | O8: Green Island | P8: 0.51041667 | Q8: Blue runner | R8: Carcharhinus perezii | S8: Caribbean Reef Shark | T8: M | U8: 178 | V8: NA | W8: NA | X8: NA | Y8: 0 | Z8: 0 | AA8: NA | AB8: NA | AC8: 596 | AD8: NA | AE8: NA | AF8: NA | AG8: NA | AH8: 0 | AI8: NA | AJ8: 0
A9: SoS | B9: 2014 | C9: October | D9: 25 | E9: UN | F9: Hilde | G9: Longline-monofyl | K9: 17.64888 | L9: -63.2311 | M9: 16 | N9: Saba Island | O9: Green Island | P9: 0.51041667 | Q9: Blue runner | R9: Ginglymostoma cirratum | S9: Nurse shark | T9: F | U9: 210 | V9: NA | W9: NA | X9: NA | Y9: 0 | Z9: 0 | AA9: NA | AB9: NA | AC9: 600 | AD9: NA | AE9: NA | AF9: NA | AG9: NA | AH9: 0 | AI9: NA | AJ9: 0
A10: SoS | B10: 2014 | C10: October | D10: 26 | E10: UN | F10: Ira | G10: Longline-SSline 1 sinker | K10: 17.61771 | L10: -63.22617 | M10: 40 | N10: Saba Island | O10: Hole in the Corner | P10: 0.70833333 | Q10: Red Hind | R10: Carcharhinus perezii | S10: Caribbean Reef Shark | T10: M | U10: 163 | V10: NA | W10: NA | X10: NA | Y10: 0 | Z10: 0 | AA10: NA | AB10: NA | AC10: 597 | AD10: NA | AE10: NA | AF10: NA | AG10: NA | AH10: 0 | AI10: NA | AJ10: 0
A11: SoS | B11: 2014 | C11: October | D11: 28 | E11: UN | F11: Jelle | G11: Longline-monofyl | K11: 17.61252 | L11: -63.23623 | M11: 16 | N11: Saba Island | O11: SE Big rock market | P11: 0.85763889 | Q11: Blackfin snapper +jap bait | R11: Ginglymostoma cirratum | S11: Nurse shark | T11: M | U11: 104 | V11: NA | W11: NA | X11: NA | Y11: 0 | Z11: 0 | AA11: NA | AB11: NA | AC11: 601 | AD11: NA | AE11: NA | AF11: NA | AG11: NA | AH11: 0 | AI11: NA | AJ11: 0
A12: SoS | B12: 2014 | C12: October | D12: 29 | E12: UN | F12: Kathy | G12: Lobster Pot | K12: 17.64888 | L12: -63.2311 | M12: 16 | N12: Saba Island | O12: Green Island (200 m E) | P12: 0.44791667 | Q12: cow-skin | R12: Ginglymostoma cirratum | S12: Nurse shark | T12: F | U12: 105 | V12: NA | W12: NA | X12: NA | Y12: 0 | Z12: 0 | AA12: NA | AB12: NA | AC12: 599 | AD12: NA | AE12: NA | AF12: NA | AG12: NA | AH12: 0 | AI12: NA | AJ12: 0 | AK12: set for several weeks, nurse shark was very lively
A13: SoS | B13: 2014 | C13: October | D13: 29 | E13: UN | F13: Lea | G13: Lobster Pot | K13: 17.64888 | L13: -63.2311 | M13: 18 | N13: Saba Island | O13: Green Island (400 m E) | P13: 0.45486111 | Q13: cow-skin | R13: Ginglymostoma cirratum | S13: Nurse shark | T13: F | U13: 94 | V13: NA | W13: NA | X13: NA | Y13: 0 | Z13: 0 | AA13: NA | AB13: NA | AC13: 598 | AD13: NA | AE13: NA | AF13: NA | AG13: NA | AH13: 0 | AI13: NA | AJ13: 0 | AK13: set for several weeks, nurse shark was very lively
A14: SoS | B14: 2015 | C14: October | D14: 31 | E14: UN | F14: Mel | G14: Rod-Hook | K14: 17.64888 | L14: -63.2311 | M14: 15 | N14: SXM | O14: Fish Bowl | P14: 0.58333333 | Q14: pilchard head | R14: Ginglymostoma cirratum | S14: Nurse shark | T14: M | U14: 120 | V14: NA | W14: NA | X14: NA | Y14: 0 | Z14: 0 | AA14: NA | AB14: NA | AC14: 20564 | AD14: 1226325 | AE14: NA | AF14: NA | AG14: NA | AH14: 0 | AI14: NA | AJ14: 0
A15: SoS | B15: 2015 | C15: July | D15: 11 | E15: UN | F15: Noor | G15: Rod-Hook | K15: 17.9881 | L15: -63.05137 | M15: 27 | N15: St. Eustatius | O15: The Gorge | P15: 0.67708333 | Q15: fresh barracuda | R15: Ginglymostoma cirratum | S15: Nurse shark | T15: F | U15: 206 | V15: NA | W15: NA | X15: NA | Y15: 0 | Z15: 0 | AA15: NA | AB15: NA | AC15: 20565 | AD15: 1226326 | AE15: NA | AF15: NA | AG15: NA | AH15: 0 | AI15: NA | AJ15: 0 | AK15: few remora's accompagning it and waiting near the boat until the nurse was released again!
A16: SoS | B16: 2015 | C16: November | D16: 11 | E16: UN | F16: Olivia | G16: Rod-Hook | K16: 17.40118 | L16: -63.19963 | M16: 16 | N16: Saba Bank | O16: Saba Bank | P16: 0.4375 | Q16: Jap bait/barracuda | R16: Carcharhinus perezii | S16: Caribbean Reef Shark | T16: F | U16: 105 | V16: NA | W16: NA | X16: NA | Y16: 0 | Z16: 0 | AA16: NA | AB16: NA | AC16: 20566 | AD16: 1226327 | AE16: NA | AF16: NA | AG16: NA | AH16: 0 | AI16: NA | AJ16: 0 | AK16: At receiver 75
A17: SoS | B17: 2015 | C17: November | D17: 11 | E17: UN | F17: Paddy | G17: Rod-Hook | K17: 17.40118 | L17: -63.19963 | M17: 16 | N17: Saba Bank | O17: Saba Bank | P17: 0.45138889 | Q17: Jap bait/barracuda | R17: Carcharhinus perezii | S17: Caribbean Reef Shark | T17: F | U17: 99 | V17: NA | W17: NA | X17: NA | Y17: 0 | Z17: 0 | AA17: NA | AB17: NA | AC17: 20567 | AD17: 1226328 | AE17: NA | AF17: NA | AG17: NA | AH17: 0 | AI17: NA | AJ17: 0 | AK17: At receiver 75
A18: SoS | B18: 2015 | C18: November | D18: 11 | E18: UN | F18: Queenie | G18: Rod-Hook | K18: 17.40118 | L18: -63.19963 | M18: 16 | N18: Saba Bank | O18: Saba Bank | P18: 0.48958333 | Q18: Jap bait/barracuda | R18: Carcharhinus perezii | S18: Caribbean Reef Shark | T18: F | U18: 103 | V18: NA | W18: NA | X18: NA | Y18: 0 | Z18: 0 | AA18: NA | AB18: NA | AC18: 20568 | AD18: 1226329 | AE18: NA | AF18: NA | AG18: NA | AH18: 0 | AI18: NA | AJ18: 0 | AK18: At receiver 75
A19: SoS | B19: 2015 | C19: November | D19: 11 | E19: UN | F19: Rebecca | G19: Rod-Hook | K19: 17.40118 | L19: -63.19963 | M19: 16 | N19: Saba Bank | O19: Saba Bank | P19: 0.49097222 | Q19: Jap bait/barracuda | R19: Ginglymostoma cirratum | S19: Nurse shark | T19: F | U19: 163 | V19: NA | W19: NA | X19: NA | Y19: 0 | Z19: 0 | AA19: NA | AB19: NA | AC19: 20569 | AD19: 1226330 | AE19: NA | AF19: NA | AG19: NA | AH19: 0 | AI19: NA | AJ19: 0 | AK19: At receiver 75
A20: SoS | B20: 2015 | C20: November | D20: 12 | E20: UN | F20: Suus | G20: Rod-Hook | K20: 17.40118 | L20: -63.19963 | M20: 16 | N20: Saba Bank | O20: Saba Bank | P20: 0.42708333 | Q20: Jap bait/barracuda | R20: Carcharhinus perezii | S20: Caribbean Reef Shark | T20: M | U20: 109 | V20: NA | W20: NA | X20: NA | Y20: 0 | Z20: 0 | AA20: NA | AB20: NA | AC20: 20570 | AD20: 1226331 | AE20: NA | AF20: NA | AG20: NA | AH20: 0 | AI20: NA | AJ20: 0 | AK20: At receiver 75
A21: SoS | B21: 2015 | C21: November | D21: 12 | E21: UN | F21: Tadzio | G21: Rod-Hook | K21: 17.40118 | L21: -63.19963 | M21: 16 | N21: Saba Bank | O21: Saba Bank | P21: 0.48263889 | Q21: Jap bait/barracuda | R21: Carcharhinus perezii | S21: Caribbean Reef Shark | T21: M | U21: 112 | V21: NA | W21: NA | X21: NA | Y21: 0 | Z21: 0 | AA21: NA | AB21: NA | AC21: 20571 | AD21: 1226332 | AE21: NA | AF21: NA | AG21: NA | AH21: 0 | AI21: NA | AJ21: 0 | AK21: At receiver 75
A22: SoS | B22: 2016 | C22: January | D22: 13 | E22: UN | F22: Urs | G22: Rod-Hook | K22: 17.44647 | L22: -63.59173 | M22: 40 | N22: Saba Bank | O22: Saba Bank | P22: 0.42708333 | Q22: Jap bait | R22: Carcharhinus perezii | S22: Caribbean Reef Shark | T22: M | U22: 142 | V22: NA | W22: NA | X22: NA | Y22: 0 | Z22: 0 | AA22: NA | AB22: NA | AC22: 20572 | AD22: 1226333 | AE22: NA | AF22: NA | AG22: NA | AH22: 0 | AI22: NA | AJ22: 0 | AK22: At receiver 77 (wreck)
A23: SoS | B23: 2016 | C23: January | D23: 13 | E23: UN | F23: Vera | G23: Rod-Hook | K23: 17.44647 | L23: -63.59173 | M23: 40 | N23: Saba Bank | O23: Saba Bank | P23: 0.4375 | Q23: Jap bait | R23: Carcharhinus perezii | S23: Caribbean Reef Shark | T23: F | U23: 162 | V23: NA | W23: NA | X23: NA | Y23: 0 | Z23: 0 | AA23: NA | AB23: NA | AC23: 20573 | AD23: 1226334 | AE23: NA | AF23: NA | AG23: NA | AH23: 0 | AI23: NA | AJ23: 0 | AK23: At receiver 77 (wreck)
A24: SoS | B24: 2016 | C24: January | D24: 13 | E24: UN | F24: Wulf | G24: Rod-Hook | K24: 17.44647 | L24: -63.59173 | M24: 40 | N24: Saba Bank | O24: Saba Bank | P24: 0.47916667 | Q24: Jap bait | T24: M | U24: 113 | V24: NA | W24: NA | X24: NA | Y24: 0 | Z24: 0 | AA24: NA | AB24: NA | AC24: 20574 | AD24: 1226335 | AE24: NA | AF24: NA | AG24: NA | AH24: 0 | AI24: NA | AJ24: 0 | AK24: At receiver 77 (wreck)
A25: SoS | B25: 2016 | C25: January | D25: 13 | E25: UN | F25: Xena | G25: Rod-Hook | K25: 17.44647 | L25: -63.59173 | M25: 40 | N25: Saba Bank | O25: Saba Bank | P25: 0.52083333 | Q25: Jap bait | R25: Carcharhinus perezii | S25: Caribbean Reef Shark | T25: F | U25: 150 | V25: NA | W25: NA | X25: NA | Y25: 0 | Z25: 0 | AA25: NA | AB25: NA | AC25: 20575 | AD25: 1226336 | AE25: NA | AF25: NA | AG25: NA | AH25: 0 | AI25: NA | AJ25: 0 | AK25: At receiver 77 (wreck)
A26: SoS | B26: 2016 | C26: January | D26: 14 | E26: UN | F26: Yvette | G26: Rod-Hook | K26: 0.646 nm east from receiver 76 | L26: UN | M26: 40 | N26: Saba Bank | O26: Saba Bank | P26: 0.41666667 | Q26: barracuda | R26: Carcharhinus perezii | S26: Caribbean Reef Shark | T26: F | U26: 171 | V26: NA | W26: NA | X26: NA | Y26: 0 | Z26: 0 | AA26: NA | AB26: NA | AC26: 20576 | AD26: 1226337 | AE26: NA | AF26: NA | AG26: NA | AH26: 0 | AI26: NA | AJ26: 0 | AK26: 0.646 nm east from receiver 76
A27: SoS | B27: 2016 | C27: January | D27: 19 | E27: UN | F27: Zorro | G27: Rod-Hook | K27: 17.40118 | L27: -63.19963 | M27: 27 | N27: St. Eustatius | O27: The Gorge | P27: 0.4375 | Q27: barracuda | R27: Carcharhinus perezii | S27: Caribbean Reef Shark | T27: M | U27: 155 | V27: NA | W27: NA | X27: NA | Y27: 0 | Z27: 0 | AA27: NA | AB27: NA | AC27: 20577 | AD27: 1226338 | AE27: NA | AF27: NA | AG27: NA | AH27: 0 | AI27: NA | AJ27: 0 | AK27: Grand Canyon near receiver 480311
A28: SoS | B28: 2016 | C28: January | D28: 19 | E28: UN | F28: Angel | G28: Rod-Hook | K28: 17.40118 | L28: -63.19963 | M28: 27 | N28: St. Eustatius | O28: The Gorge | P28: 0.48958333 | Q28: barracuda | R28: Carcharhinus perezii | S28: Caribbean Reef Shark | T28: F | U28: 148 | V28: NA | W28: NA | X28: NA | Y28: 0 | Z28: 0 | AA28: NA | AB28: NA | AC28: 20578 | AD28: 1226339 | AE28: NA | AF28: NA | AG28: NA | AH28: 0 | AI28: NA | AJ28: 0 | AK28: Grand Canyon near receiver 480311
A29: SoS | B29: 2016 | C29: January | D29: 19 | E29: UN | F29: Belle | G29: Rod-Hook | K29: 17.40118 | L29: -63.19963 | M29: 27 | N29: St. Eustatius | O29: The Gorge | P29: 0.54166667 | Q29: barracuda | R29: Carcharhinus perezii | S29: Caribbean Reef Shark | T29: F | U29: 102 | V29: NA | W29: NA | X29: NA | Y29: 0 | Z29: 0 | AA29: NA | AB29: NA | AC29: 20579 | AD29: 1226340 | AE29: NA | AF29: NA | AG29: NA | AH29: 0 | AI29: NA | AJ29: 0 | AK29: Grand Canyon near receiver 480311
A30: SoS | B30: 2014 | C30: November | D30: 23 | E30: UN | F30: NA | G30: Rod-Hook | K30: 17.64614 | L30: -63.26499 | M30: UN | N30: Saba Island | O30: Shark Shoal | P30: 0.54166667 | Q30: UN | R30: Carcharhinus perezii | S30: Caribbean Reef Shark | T30: M | U30: 150 | V30: NA | W30: NA | X30: NA | Y30: 0 | Z30: 0 | AA30: NA | AB30: NA | AC30: NA | AD30: 23809 | AE30: NA | AF30: NA | AG30: NA | AH30: 0 | AI30: NA | AJ30: 0
A31: SoS | B31: 2015 | C31: November | D31: 23 | E31: UN | F31: NA | G31: Rod-Hook | K31: 17.64614 | L31: -63.26499 | M31: UN | N31: Saba Island | O31: Shark Shoal | P31: 0.56944444 | Q31: UN | R31: Carcharhinus perezii | S31: Caribbean Reef Shark | T31: F | U31: 184 | V31: NA | W31: NA | X31: NA | Y31: 0 | Z31: 0 | AA31: NA | AB31: NA | AC31: NA | AD31: 23810 | AE31: NA | AF31: NA | AG31: NA | AH31: 0 | AI31: NA | AJ31: 0
A32: SoS | B32: 2014 | C32: November | D32: 24 | E32: UN | F32: NA | G32: Rod-Hook | K32: 17.63205 | L32: -63.2743 | M32: UN | N32: Saba Island | O32: Third Encounter | P32: 0.39583333 | Q32: UN | R32: Carcharhinus perezii | S32: Caribbean Reef Shark | T32: F | U32: 180 | V32: NA | W32: NA | X32: NA | Y32: 0 | Z32: 0 | AA32: NA | AB32: NA | AC32: NA | AD32: 23811 | AE32: NA | AF32: NA | AG32: NA | AH32: 0 | AI32: NA | AJ32: 0
A33: SoS | B33: 2015 | C33: November | D33: 24 | E33: UN | F33: NA | G33: Rod-Hook | K33: 17.6328 | L33: -63.27462 | M33: UN | N33: Saba Island | O33: Twilight Zone | P33: 0.52430556 | Q33: UN | R33: Carcharhinus perezii | S33: Caribbean Reef Shark | T33: F | U33: 131 | V33: NA | W33: NA | X33: NA | Y33: 0 | Z33: 0 | AA33: NA | AB33: NA | AC33: NA | AD33: 23812 | AE33: NA | AF33: NA | AG33: NA | AH33: 0 | AI33: NA | AJ33: 0
A34: SoS | B34: 2016 | C34: November | D34: 24 | E34: UN | F34: NA | G34: Rod-Hook | K34: 17.6328 | L34: -63.27462 | M34: UN | N34: Saba Island | O34: Twilight Zone | P34: 0.53472222 | Q34: UN | R34: Carcharhinus perezii | S34: Caribbean Reef Shark | T34: M | U34: 115 | V34: NA | W34: NA | X34: NA | Y34: 0 | Z34: 0 | AA34: NA | AB34: NA | AC34: NA | AD34: 23813 | AE34: NA | AF34: NA | AG34: NA | AH34: 0 | AI34: NA | AJ34: 0
A35: SoS | B35: 2017 | C35: November | D35: 24 | E35: UN | F35: NA | G35: Rod-Hook | K35: 17.6328 | L35: -63.27462 | M35: UN | N35: Saba Island | O35: Twilight Zone | P35: 0.57291667 | Q35: UN | R35: Carcharhinus perezii | S35: Caribbean Reef Shark | T35: F | U35: 125 | V35: NA | W35: NA | X35: NA | Y35: 0 | Z35: 0 | AA35: NA | AB35: NA | AC35: NA | AD35: 23814 | AE35: NA | AF35: NA | AG35: NA | AH35: 0 | AI35: NA | AJ35: 0
A36: SoS | B36: 2015 | C36: November | D36: 25 | E36: UN | F36: NA | G36: Longline | K36: 17.64888 | L36: -63.2311 | M36: UN | N36: Saba Island | O36: Green Island | P36: 0.51041667 | Q36: UN | R36: Carcharhinus perezii | S36: Caribbean Reef Shark | T36: M | U36: 178 | V36: NA | W36: NA | X36: NA | Y36: 0 | Z36: 0 | AA36: NA | AB36: NA | AC36: NA | AD36: 23815 | AE36: NA | AF36: NA | AG36: NA | AH36: 0 | AI36: NA | AJ36: 0
A37: SoS | B37: 2014 | C37: November | D37: 26 | E37: UN | F37: NA | G37: Longline | K37: 17.61771 | L37: -63.22617 | M37: UN | N37: Saba Island | O37: Hole in the Corner | P37: 0.70833333 | Q37: UN | R37: Carcharhinus perezii | S37: Caribbean Reef Shark | T37: M | U37: 163 | V37: NA | W37: NA | X37: NA | Y37: 0 | Z37: 0 | AA37: NA | AB37: NA | AC37: NA | AD37: 23816 | AE37: NA | AF37: NA | AG37: NA | AH37: 0 | AI37: NA | AJ37: 0
A38: SoS | B38: 2015 | C38: November | D38: 29 | E38: UN | F38: NA | G38: Lobster Pot | K38: 17.64888 | L38: -63.2311 | M38: UN | N38: Saba Island | O38: Green Island (400 m E) | P38: 0.45486111 | Q38: UN | R38: Ginglymostoma cirratum | S38: Nurse shark | T38: F | U38: 94 | V38: NA | W38: NA | X38: NA | Y38: 0 | Z38: 0 | AA38: NA | AB38: NA | AC38: NA | AD38: 23817 | AE38: NA | AF38: NA | AG38: NA | AH38: 0 | AI38: NA | AJ38: 0
A39: SoS | B39: 2014 | C39: November | D39: 29 | E39: UN | F39: NA | G39: Lobster Pot | K39: 17.64888 | L39: -63.2311 | M39: UN | N39: Saba Island | O39: Green Island (200 m E) | P39: 0.44791667 | Q39: UN | R39: Ginglymostoma cirratum | S39: Nurse shark | T39: F | U39: 105 | V39: NA | W39: NA | X39: NA | Y39: 0 | Z39: 0 | AA39: NA | AB39: NA | AC39: NA | AD39: 23818 | AE39: NA | AF39: NA | AG39: NA | AH39: 0 | AI39: NA | AJ39: 0
A40: SoS | B40: 2016 | C40: November | D40: 25 | E40: UN | F40: NA | G40: Longline | K40: 17.64888 | L40: -63.2311 | M40: UN | N40: Saba Island | O40: Green Island | P40: 0.51041667 | Q40: UN | R40: Ginglymostoma cirratum | S40: Nurse shark | T40: F | U40: 210 | V40: NA | W40: NA | X40: NA | Y40: 0 | Z40: 0 | AA40: NA | AB40: NA | AC40: NA | AD40: 23819 | AE40: NA | AF40: NA | AG40: NA | AH40: 0 | AI40: NA | AJ40: 0
...

Sheet Sets
A1: year | B1: month | C1: date | D1: location | E1: site | F1: waypoint | G1: method | H1: latitude | I1: longitude | J1: depth_(m) | K1: set | L1: check | M1: hook_number | N1: time_in | O1: time_in_cor | P1: time_check_1 | Q1: time_check_2 | R1: time_check_3 | S1: time_haul | T1: time_haul_cor | U1: bait | V1: result | W1: comments
A2: 2016 | B2: October | C2: 2 | D2: The Bridge | F2: 230 | G2: DL | H2: 18.01.182 | I2: 63.06.266 | J2: 46 | M2: 1 | N2: 0.36111111 | O2: 08:40:00 | P2: 0.43055556 | Q2: - | R2: - | S2: 0.47013889 | T2: 11:17:00 | U2: BRH | V2: -
A3: 2016 | B3: October | C3: 2 | D3: The Bridge | F3: 231 | G3: DL | H3: 18.01.059 | I3: 63.06.106 | J3: 44 | M3: 2 | N3: 0.36597222 | O3: 08:47:00 | P3: 0.43402778 | Q3: - | R3: - | S3: 0.48263889 | T3: 11:35:00 | U3: BRH+BRT | V3: Shark 9
A4: 2016 | B4: October | C4: 2 | D4: The Bridge | F4: 232 | G4: DL | H4: 18.01.007 | I4: 63.05.926 | J4: 46.5 | M4: 3 | N4: 0.36805556 | O4: 08:50:00 | P4: 0.4375 | Q4: 0.50138889 | R4: - | S4: 0.51458333 | T4: 12:21:00 | U4: BRH | V4: -
A5: 2016 | B5: October | C5: 2 | D5: Moonscape | F5: 233 | G5: DL | H5: 18.00.645 | I5: 63.05.645 | J5: 45.8 | M5: 4 | N5: 0.37430556 | O5: 08:59:00 | P5: 0.44097222 | Q5: - | R5: - | S5: 0.50347222 | T5: 12:05:00 | U5: BRT | V5: -
A6: 2016 | B6: October | C6: 2 | D6: Moonscape | F6: 234 | G6: DL | H6: 18.00.899 | I6: 63.05.378 | J6: 37.5 | M6: 5 | N6: 0.37847222 | O6: 09:05:00 | P6: 0.44375 | Q6: - | R6: - | S6: 0.50694444 | T6: 12:10:00 | U6: BRH | V6: -
A7: 2016 | B7: October | C7: 2 | D7: The Bridge | F7: 235 | G7: DL | H7: 18.01.308 | I7: 63.06.478 | J7: 47 | M7: 6 | N7: 0.47013889 | O7: 11:17:00 | P7: - | Q7: - | R7: - | S7: 0.51180556 | T7: 12:17:00 | U7: BRH | V7: -
A8: 2016 | B8: October | C8: 7 | D8: Beacon Hill | F8: 236 | G8: DL | H8: 18.02.238 | I8: 63.06.620 | J8: 23.4 | M8: 1 | N8: 0.43402778 | O8: 10:25:00 | P8: 0.50347222 | Q8: 0.59027778 | R8: - | S8: 0.75 | T8: 18:00:00 | U8: BM/BM/BM+SN | V8: -
A9: 2016 | B9: October | C9: 7 | D9: Beacon Hill | F9: 237 | G9: DL | H9: 18.01.893 | I9: 63.06.635 | J9: 33.9 | M9: 2 | N9: 0.44652778 | O9: 10:43:00 | P9: 0.50972222 | Q9: 0.59305556 | R9: - | S9: 0.72916667 | T9: 17:30:00 | U9: BM/BM+SN | V9: Shark 14
A10: 2016 | B10: October | C10: 7 | D10: Beacon Hill | F10: 238 | G10: DL | H10: 18.01.736 | I10: 63.06.758 | J10: 42.4 | M10: 3 | N10: 0.44722222 | O10: 10:44:00 | P10: 0.51111111 | Q10: - | R10: - | S10: 0.59652778 | T10: 14:19:00 | U10: BT | V10: Shark 10
A11: 2016 | B11: October | C11: 7 | D11: The Bridge | F11: 239 | G11: DL | H11: 18.01.481 | I11: 63.06.969 | J11: 46.8 | M11: 4 | N11: 0.45416667 | O11: 10:54:00 | P11: 0.51319444 | Q11: - | R11: - | S11: 0.63541667 | T11: 15:15:00 | U11: BT | V11: Shark 11
A12: 2016 | B12: October | C12: 7 | D12: The Bridge | F12: 240 | G12: DL | H12: 18.01.360 | I12: 63.07.046 | J12: 53.4 | M12: 5 | N12: 0.46041667 | O12: 11:03:00 | P12: 0.51527778 | Q12: - | R12: - | S12: 0.65972222 | T12: 15:50:00 | U12: BH | V12: -
A13: 2016 | B13: October | C13: 7 | D13: The Bridge | F13: 242 | G13: DL | H13: 18.01.310 | I13: 63.06.952 | J13: 54.4 | M13: 6 | N13: 0.46805556 | O13: 11:14:00 | P13: 0.53541667 | Q13: - | R13: - | S13: 0.66458333 | T13: 15:57:00 | U13: BM/BM | V13: Shark 12
A14: 2016 | B14: October | C14: 7 | D14: The Bridge | F14: 243 | G14: DL | H14: 18.01.226 | I14: 63.06.985 | J14: 67 | M14: 7 | N14: 0.47222222 | O14: 11:20:00 | P14: 0.5375 | Q14: - | R14: - | S14: 0.68055556 | T14: 16:20:00 | U14: BM | V14: Shark 9, recap
A15: 2016 | B15: October | C15: 7 | D15: The Bridge | F15: 244 | G15: DL | H15: 18.01.130 | I15: 63.06.883 | J15: 71.3 | M15: 8 | N15: 0.47569444 | O15: 11:25:00 | P15: 0.53888889 | Q15: - | R15: - | S15: 0.69444444 | T15: 16:40:00 | U15: BM+SN/BM+GR | V15: Shark 13
A16: 2016 | B16: October | C16: 7 | D16: The Bridge | F16: 245 | G16: DL | H16: 18.01.019 | I16: 63.06.829 | J16: 83.6 | M16: 9 | N16: 0.47916667 | O16: 11:30:00 | P16: 0.54305556 | Q16: - | R16: - | S16: 0.71875 | T16: 17:15:00 | U16: BM | V16: -
A17: 2016 | B17: October | C17: 7 | D17: The Bridge | F17: 246 | G17: DL | H17: 18.00.916 | I17: 63.06.762 | J17: 94.9 | M17: 10 | N17: 0.48402778 | O17: 11:37:00 | P17: 0.54513889 | Q17: - | R17: - | S17: 0.71944444 | T17: 17:16:00 | U17: BH | V17: -
A18: 2016 | B18: October | C18: 9 | D18: Beacon Hill | F18: 247 | G18: DL | H18: 18.02.142 | I18: 63.07.068 | J18: 15.3 | M18: 1 | N18: 0.44791667 | O18: 10:45:00 | P18: 0.51736111 | Q18: 0.58333333 | R18: - | S18: 0.62708333 | T18: 15:03:00 | U18: BM+GR | V18: -
A19: 2016 | B19: October | C19: 9 | D19: Beacon Hill | F19: 248 | G19: DL | H19: 18.02.102 | I19: 63.07.119 | J19: 26.5 | M19: 2 | N19: 0.45138889 | O19: 10:50:00 | P19: 0.51944444 | Q19: 0.58680556 | R19: - | S19: 0.62847222 | T19: 15:05:00 | U19: BM/BT | V19: -
A20: 2016 | B20: October | C20: 9 | D20: Beacon Hill | F20: 249 | G20: DL | H20: 18.02.017 | I20: 63.07.169 | J20: 34.3 | M20: 3 | N20: 0.45486111 | O20: 10:55:00 | P20: 0.52083333 | Q20: 0.58888889 | R20: - | S20: 0.63055556 | T20: 15:08:00 | U20: BT | V20: -
A21: 2016 | B21: October | C21: 9 | D21: Beacon Hill | F21: 250 | G21: DL | H21: 18.02.001 | I21: 63.07.244 | J21: 40 | M21: 4 | N21: 0.45694444 | O21: 10:58:00 | P21: 0.52569444 | Q21: 0.59305556 | R21: - | S21: 0.63194444 | T21: 15:10:00 | U21: BM | V21: -
A22: 2016 | B22: October | C22: 9 | D22: Beacon Hill | F22: 251 | G22: DL | H22: 18.01.927 | I22: 63.07.380 | J22: 40 | M22: 5 | N22: 0.45833333 | O22: 11:00:00 | P22: 0.52777778 | Q22: 0.59583333 | R22: - | S22: 0.63333333 | T22: 15:12:00 | U22: BH/BM | V22: -
A23: 2016 | B23: October | C23: 9 | D23: Beacon Hill | F23: 252 | G23: DL | H23: 18.01.904 | I23: 63.07.531 | J23: 41.7 | M23: 6 | N23: 0.46180556 | O23: 11:05:00 | P23: 0.53055556 | Q23: 0.59722222 | R23: - | S23: 0.63611111 | T23: 15:16:00 | U23: BM+GR/BM | V23: -
A24: 2016 | B24: October | C24: 9 | D24: Beacon Hill | F24: 253 | G24: DL | H24: 18.01.892 | I24: 63.07.652 | J24: 55.2 | M24: 7 | N24: 0.46388889 | O24: 11:08:00 | P24: 0.53333333 | Q24: 0.60138889 | R24: - | S24: 0.6375 | T24: 15:18:00 | U24: BM/BH | V24: -
A25: 2016 | B25: October | C25: 9 | D25: Porpoise | F25: 254 | G25: DL | H25: 18.01.881 | I25: 63.07.733 | J25: 65.6 | M25: 8 | N25: 0.46597222 | O25: 11:11:00 | P25: 0.53611111 | Q25: 0.60416667 | R25: - | S25: 0.64236111 | T25: 15:25:00 | U25: BM | V25: -
A26: 2016 | B26: October | C26: 9 | D26: Porpoise | F26: 255 | G26: DL | H26: 18.01.833 | I26: 63.07.802 | J26: 86.1 | M26: 9 | N26: 0.46875 | O26: 11:15:00 | P26: 0.53958333 | Q26: 0.60694444 | R26: - | S26: 0.64444444 | T26: 15:28:00 | U26: BT+GR/BM | V26: -
A27: 2016 | B27: October | C27: 9 | D27: Porpoise | F27: 256 | G27: DL | H27: 18.01.737 | I27: 63.07.798 | J27: 103.4 | M27: 10 | N27: 0.47222222 | O27: 11:20:00 | P27: 0.54166667 | Q27: 0.61111111 | R27: - | S27: 0.64791667 | T27: 15:33:00 | U27: BH/BM | V27: -
A28: 2016 | B28: October | C28: 10 | D28: Pelican | F28: 257 | G28: DL | H28: 18.01.539 | I28: 63.05.667 | J28: 16.1 | M28: 1 | N28: 0.37569444 | O28: 09:01:00 | P28: 0.45833333 | Q28: 0.53888889 | R28: - | S28: 0.56388889 | T28: 13:32:00 | U28: BM | V28: -
A29: 2016 | B29: October | C29: 10 | D29: Pelican | F29: 258 | G29: DL | H29: 18.01.348 | I29: 63.05.807 | J29: 27.1 | M29: 2 | N29: 0.37916667 | O29: 09:06:00 | P29: 0.46180556 | Q29: 0.54097222 | R29: - | S29: 0.56597222 | T29: 13:35:00 | U29: BT/BM | V29: -
A30: 2016 | B30: October | C30: 10 | D30: Charlie Shoal | F30: 259 | G30: DL | H30: 18.01.131 | I30: 63.06.071 | J30: 31.1 | M30: 3 | N30: 0.38333333 | O30: 09:12:00 | P30: 0.46458333 | Q30: 0.54305556 | R30: 0.60069444 | S30: 0.67152778 | T30: 16:07:00 | U30: BM/BT | V30: Shark 15
A31: 2016 | B31: October | C31: 10 | D31: Charlie Shoal | F31: 260 | G31: DL | H31: 18.01.069 | I31: 63.06.192 | J31: 49.7 | M31: 4 | N31: 0.38541667 | O31: 09:15:00 | P31: 0.46666667 | Q31: 0.54444444 | R31: 0.60208333 | S31: 16:44:00 | T31: 16:44:00 | U31: BH | V31: Shark 16
A32: 2016 | B32: October | C32: 10 | D32: The Bridge | F32: 261 | G32: DL | H32: 18.01.107 | I32: 63.06.315 | J32: 55.1 | M32: 5 | N32: 0.3875 | O32: 09:18:00 | P32: 0.46805556 | Q32: 0.54583333 | R32: 0.60694444 | S32: 0.70972222 | T32: 17:02:00 | U32: BM/BM+SN | V32: -
A33: 2016 | B33: October | C33: 10 | D33: The Bridge | F33: 262 | G33: DL | H33: 18.01.217 | I33: 63.06.367 | J33: 51.1 | M33: 6 | N33: 0.38958333 | O33: 09:21:00 | P33: 0.47013889 | Q33: 0.54722222 | R33: 0.60902778 | S33: 0.72916667 | T33: 17:30:00 | U33: BM | V33: -
A34: 2016 | B34: October | C34: 10 | D34: The Bridge | F34: 263 | G34: DL | H34: 18.00.973 | I34: 63.06.623 | J34: 60.2 | M34: 7 | N34: 0.39236111 | O34: 09:25:00 | P34: 0.47222222 | Q34: 0.55 | R34: 0.61180556 | S34: 0.7125 | T34: 17:06:00 | U34: BM/BM+SN | V34: -
A35: 2016 | B35: October | C35: 10 | D35: The Bridge | F35: 264 | G35: DL | H35: 18.00.847 | I35: 63.06.575 | J35: 73.1 | M35: 8 | N35: 0.39513889 | O35: 09:29:00 | P35: 0.475 | Q35: 0.55277778 | R35: 0.61388889 | S35: 0.72569444 | T35: 17:25:00 | U35: BT | V35: -
A36: 2016 | B36: October | C36: 10 | D36: The Bridge | F36: 265 | G36: DL | H36: 18.01.006 | I36: 63.06.826 | J36: 85 | M36: 9 | N36: 0.39791667 | O36: 09:33:00 | P36: 0.47708333 | Q36: 0.55555556 | R36: 0.61666667 | S36: 0.72152778 | T36: 17:19:00 | U36: BH | V36: -
A37: 2016 | B37: October | C37: 10 | D37: The Bridge | F37: 267 | G37: DL | H37: 18.00.976 | I37: 63.06.992 | J37: 106.4 | M37: 10 | N37: 0.40069444 | O37: 09:37:00 | P37: 0.47847222 | Q37: 0.55763889 | R37: 0.11875 | S37: 0.72013889 | T37: 17:17:00 | U37: BM | V37: -
A38: 2016 | B38: October | C38: 10 | D38: Beacon Hill | F38: 268 | G38: DLB | H38: 18.02.241 | I38: 63.06.678 | J38: 21.4 | M38: 1 | N38: 0.56944444 | O38: 13:40:00 | P38: 0.62291667 | Q38: - | R38: - | S38: 0.73194444 | T38: 17:34:00 | U38: BM | V38: -
A39: 2016 | B39: October | C39: 10 | D39: Beacon Hill | F39: 269 | G39: DLB | H39: 18.02.076 | I39: 63.06.604 | J39: 24.8 | M39: 2 | N39: 0.57222222 | O39: 13:44:00 | P39: 0.62569444 | Q39: - | R39: - | S39: 0.73611111 | T39: 17:40:00 | U39: BH | V39: Shark 17
A40: 2016 | B40: October | C40: 12 | D40: Point Blanche | F40: 270 | G40: DL | H40: 18.00.650 | I40: 63.01.961 | J40: 32 | M40: 1 | N40: 0.36666667 | O40: 08:48:00 | P40: - | Q40: - | R40: - | S40: 0.43819444 | T40: 10:31:00 | U40: BM | V40: -
...

Sheet BRUV
A1: year | B1: month | C1: day | D1: latitude | E1: longitude | F1: location | G1: site | H1: drop | I1: depth_(ft) | J1: camera | K1: bait | L1: bait_result | M1: time_in | N1: time_out | O1: wind_(kt) | P1: sea_(m) | Q1: swell_(m) | R1: cloud_cover | S1: tide | T1: comments
A2: 2021 | B2: 8 | C2: 1 | D2: 17°32.997 | E2: 63°16.757 | F2: Saba_bank | G2: moonfish_reef | H2: 1 | I2: 76 | J2: hero_4 | K2: lionfish | L2: BU | M2: 0.34444444 | N2: 0.475 | O2: 12 | P2: 1 | Q2: 3 (ft) | R2: 0.2 | S2: High
A3: 2021 | B3: 8 | C3: 1 | D3: 17°33.964 | E3: 63°18.133 | F3: Saba_bank | G3: moonfish_reef | H3: 2 | I3: 76 | J3: hero_5 | K3: lionfish | M3: 0.59444444 | N3: 0.64583333 | O3: 12 | P3: 1 | Q3: 1 | R3: 0.1 | S3: Low
A4: 2021 | B4: 8 | C4: 2 | D4: 17°33.710 | E4: 63°17.717 | F4: Saba_bank | G4: moonfish_reef | H4: 1 | I4: 62 | J4: hero_5 | K4: grunt | L4: BU | M4: 0.32361111 | N4: 0.37291667 | O4: 12 | P4: 1 | Q4: 1 | R4: 0.1 | S4: Medium
A5: 2021 | B5: 8 | C5: 2 | D5: 17°33.432 | E5: 63°17.311 | F5: Saba_bank | G5: moonfish_reef | H5: 1 | I5: 60 | J5: hero_8 | K5: grunt | L5: BB | M5: 0.34236111 | N5: 0.47430556 | O5: 12 | P5: 1 | Q5: 1 | R5: 0.1 | S5: Medium | T5: Camera not on
A6: 2021 | B6: 8 | C6: 2 | D6: 17°34.070 | E6: 63°18.236 | F6: Saba_bank | G6: moonfish_reef | H6: 2 | I6: 89 | J6: hero_5 | K6: grunt | L6: BU | M6: 0.375 | N6: 0.60555556 | O6: 10 | P6: 1.5 | Q6: 1 | R6: 0.15 | S6: Medium
A7: 2021 | B7: 8 | C7: 2 | D7: 17°32.440 | E7: 63°17.306 | F7: Saba_bank | G7: moonfish_reef | H7: 2 | I7: 55 | J7: hero_8 | K7: BH | L7: BG | M7: 0.47638889 | N7: 0.61944444 | O7: 10 | P7: 1 | Q7: 1 | R7: 0.05 | S7: Medium
A8: 2021 | B8: 8 | C8: 2 | D8: 17°33.504 | E8: 63°17.240 | F8: Saba_bank | G8: moonfish_reef | H8: 3 | I8: 67 | J8: hero_8 | K8: BT | L8: BU | M8: 0.62430556 | N8: 0.67708333 | O8: 10 | P8: 1.2 | Q8: 1 | R8: 0.2 | S8: Low
A9: 2021 | B9: 8 | C9: 3 | D9: 17°30.079 | E9: 63°14.533 | F9: Saba_bank | G9: poison_bank | H9: 1 | I9: 44 | J9: hero_5 | K9: parrotfish | L9: BG | M9: 0.34166667 | N9: 0.39722222 | O9: 12.5 | P9: 1 | Q9: 1.5 | R9: 0.15 | S9: High
A10: 2021 | B10: 8 | C10: 3 | D10: 17°29.292 | E10: 63°14.024 | F10: Saba_bank | G10: poison_bank | H10: 1 | I10: 46 | J10: hero_8 | K10: surgeonfish | L10: BG | M10: 0.35486111 | N10: 0.46458333 | O10: 12.5 | P10: 1 | Q10: 1.5 | R10: 0.15 | S10: High
A11: 2021 | B11: 8 | C11: 3 | D11: 17°30.044 | E11: 63°14.544 | F11: Saba_bank | G11: poison_bank | H11: 2 | I11: 48 | J11: hero_5 | K11: coney | L11: BG | M11: 0.40069444 | N11: 0.48472222 | O11: 15 | P11: 1 | Q11: 1.5 | R11: 0 | S11: High
A12: 2021 | B12: 8 | C12: 3 | D12: 17°29.351 | E12: 63°14.032 | F12: Saba_bank | G12: poison_bank | H12: 2 | I12: 45 | J12: hero_8 | K12: doctorfish | L12: BB | M12: 0.46666667 | N12: 0.6875 | O12: 15 | P12: 1 | Q12: 1.5 | R12: 0 | S12: High
A13: 2021 | B13: 8 | C13: 3 | D13: 17°30.181 | E13: 63°14.510 | F13: Saba_bank | G13: poison_bank | H13: 2 | I13: 45 | J13: hero_5 | K13: doctorfish | L13: BG | M13: 0.4875 | N13: 0.60902778 | O13: 15 | P13: 1 | Q13: 1.5 | R13: 0.05 | S13: High
A14: 2021 | B14: 8 | C14: 4 | D14: 17°33.466 | E14: 63°17.030 | F14: Saba_bank | G14: moonfish_reef | H14: 1 | I14: 67 | J14: hero_8 | K14: queentriggerfish_skin | L14: BU | M14: 0.45277778 | N14: 0.52638889 | O14: 16.5 | P14: 1.9 | Q14: 4.5 | R14: 0.7 | S14: High | T14: Camera on an angle
A15: 2021 | B15: 8 | C15: 4 | D15: 17°32.564 | E15: 63°16.616 | F15: Saba_bank | G15: moonfish_reef | H15: 1 | I15: 62 | J15: hero_5 | K15: queentriggerfish_skin | L15: BU | M15: 0.46875 | N15: 0.55486111 | O15: 16.5 | P15: 1.9 | Q15: 4.5 | R15: 0.5 | S15: High
A16: 2021 | B16: 8 | C16: 4 | D16: 17°33.492 | E16: 63°17.085 | F16: Saba_bank | G16: moonfish_reef | H16: 2 | I16: 66 | J16: hero_8 | K16: queentriggerfish_skin | L16: BU | M16: 0.52847222 | N16: 0.60069444 | O16: 16.5 | P16: 1.9 | Q16: 4.5 | R16: 0.4 | S16: High
A17: 2021 | B17: 8 | C17: 4 | D17: 17°32.650 | E17: 63°16.601 | F17: Saba_bank | G17: moonfish_reef | H17: 2 | I17: 63 | J17: hero_5 | K17: queentriggerfish_skin | L17: BU | M17: 0.55763889 | N17: 0.63541667 | O17: 16.5 | P17: 1.9 | Q17: 6 | R17: 0.6 | S17: High
A18: 2021 | B18: 8 | C18: 5 | D18: 17°30.222 | E18: 63°14.327 | F18: Saba_bank | G18: poison_bank | H18: 1 | I18: 48 | J18: hero_8 | K18: lionfish | L18: BU | M18: 0.34027778 | N18: 0.39652778 | O18: 16.5 | P18: 1.3 | Q18: 3 | R18: 0.05 | S18: High
A19: 2021 | B19: 8 | C19: 5 | D19: 17°29.217 | E19: 63°14.292 | F19: Saba_bank | G19: poison_bank | H19: 1 | I19: 43 | J19: hero_5 | K19: lionfish | L19: BG | M19: 0.35069444 | N19: 0.43333333 | O19: 16.5 | P19: 1.6 | Q19: 3 | R19: 0.05 | S19: High
A20: 2021 | B20: 8 | C20: 5 | D20: 17°30.320 | E20: 63°14.586 | F20: Saba_bank | G20: poison_bank | H20: 2 | I20: 59 | J20: hero_8 | K20: lionfish | L20: BU | M20: 0.39930556 | N20: 0.45486111 | O20: 16.5 | P20: 1.6 | Q20: 3 | R20: 0.2 | S20: High
A21: 2021 | B21: 8 | C21: 5 | D21: 17°29.254 | E21: 63°14.372 | F21: Saba_bank | G21: poison_bank | H21: 2 | I21: 43 | J21: hero_5 | K21: BT | L21: BB | M21: 0.43611111 | N21: 0.49791667 | O21: 16.5 | P21: 1.3 | Q21: 3 | R21: 0.7 | S21: High
A22: 2021 | B22: 8 | C22: 5 | D22: 17°30.395 | E22: 63°14.700 | F22: Saba_bank | G22: poison_bank | H22: 3 | I22: 66 | J22: hero_8 | K22: lionfish | L22: BB | M22: 0.45902778 | N22: 0.58194444 | O22: 16.5 | P22: 1.6 | Q22: 3 | R22: 0.9 | S22: High
A23: 2021 | B23: 8 | C23: 5 | D23: 17°29.314 | E23: 63°14.453 | F23: Saba_bank | G23: poison_bank | H23: 3 | I23: 42 | J23: hero_5 | K23: BT | L23: BB | M23: 0.50069444 | N23: 0.59930556 | O23: 16.5 | P23: 2.3 | Q23: 3 | R23: 0.05 | S23: High

Sheet Locations
A1: Location | B1: Broad location
A2: Saba | B2: Saba Island (Saba National Marine Park)
A3: SXM | B3: SXM
A4: Statia | B4: St. Eustatius
A5: Saba Bank | B5: Saba Bank
A6: Gregory | B6: SXM | C6: pls confirm with Tadzio
A7: Frenchman's Reef | B7: SXM | C7: pls confirm with Tadzio
A8: The Bridge | B8: SXM | C8: pls confirm with Tadzio
A9: Beacon Hill | B9: SXM | C9: pls confirm with Tadzio
A10: Charlie Shoal | B10: SXM | C10: pls confirm with Tadzio
A11: Point Blanche | B11: SXM | C11: pls confirm with Tadzio
A12: Port | B12: SXM | C12: pls confirm with Tadzio
A13: 1_SB_South_6 | B13: Saba Bank
A14: 1_SB_South_5 | B14: Saba Bank
A15: 2_SB_South_1 | B15: Saba Bank
A16: 2_SB_South_5 | B16: Saba Bank
A17: 2_SB_South_6 | B17: Saba Bank
A18: 2_SB_South_7 | B18: Saba Bank
A19: 2_SB_South_2 | B19: Saba Bank
A20: 2_SB_South_3 | B20: Saba Bank
A21: 2_SB_South_9 | B21: Saba Bank
A22: 2_SB_South_10 | B22: Saba Bank
A23: 3_SB_East_8 | B23: Saba Bank
A24: 3_SB_East_10 | B24: Saba Bank
... A35: Saba_Marine_Park | B35: Saba Island (Saba National Marine Park)

Sheet prelim_workup
A1: Expedition duration (days) | B1: =IFERROR(__xludf.DUMMYFUNCTION("COUNTUNIQUE(Sets!C149:C1147)"),12.0) -> 12
A2: Catch:
A3: species | B3: moonfish_reef | C3: poison_bank | D3: total
A4: TS | B4: =COUNTIFS(sharks!P:P,A4,sharks!M:M,B$3) -> 0 | C4: =COUNTIFS(sharks!P:P,A4,sharks!M:M,C$3) -> 0 | D4: =COUNTIF(sharks!P:P,A4) -> #REF!
A5: CRS | B5: =COUNTIFS(sharks!P:P,A5,sharks!M:M,B$3) -> 0 | C5: =COUNTIFS(sharks!P:P,A5,sharks!M:M,C$3) -> 0 | D5: =COUNTIF(sharks!P:P,A5) -> #REF!
A6: NS | B6: =COUNTIFS(sharks!P:P,A6,sharks!M:M,B$3) -> 0 | C6: =COUNTIFS(sharks!P:P,A6,sharks!M:M,C$3) -> 0 | D6: =COUNTIF(sharks!P:P,A6) -> #REF!
A7: OT | B7: 1 | C7: 1 | D7: 2
A10: Total sets: | B10: =COUNT(Sets!L:L) -> 446
A11: catch rate: | B11: =SUM(D4:D6)/B10 -> #REF! | D11: excluding barracudas :)
A13: Science:
B14: TS | C14: CRS | D14: NS
A15: PIT | B15: =COUNTIFS(sharks!P:P,"TS",sharks!X:X,"<>-") -> 0 | C15: =COUNTIFS(sharks!P:P,"CRS",sharks!X:X,"<>-") -> 0 | D15: =COUNTIFS(sharks!P:P,"NS",sharks!X:X,"<>-") -> 0
A16: FLOY | B16: =COUNTIFS(sharks!P:P,"TS",sharks!Y:Y,"<>-") -> 0 | C16: =COUNTIFS(sharks!P:P,"CRS",sharks!Y:Y,"<>-") -> 0 | D16: =COUNTIFS(sharks!P:P,"NS",sharks!Y:Y,"<>-") -> 0
A17: satellite | B17: =COUNTIFS(sharks!P:P,"TS",sharks!Z:Z,"<>-") -> 0 | C17: =COUNTIFS(sharks!P:P,"CRS",sharks!Z:Z,"<>-") -> 0 | D17: =COUNTIFS(sharks!P:P,"NS",sharks!Z:Z,"<>-") -> 0
A18: ultrasound | B18: =COUNTIFS(sharks!P:P,"TS",sharks!AB:AB,"<>-") -> 0 | C18: =COUNTIFS(sharks!P:P,"CRS",sharks!AB:AB,"<>-") -> 0 | D18: =COUNTIFS(sharks!P:P,"NS",sharks!AB:AB,"<>-") -> 0
A19: DNA | B19: =SUMIF(sharks!P:P,"TS",sharks!V:V) -> #N/A | C19: =SUMIF(sharks!P:P,"CRS",sharks!V:V) -> #N/A | D19: =SUMIF(sharks!P:P,"NS",sharks!V:V) -> #N/A
A20: blood | B20: =COUNTIFS(sharks!P:P,"TS",sharks!W:W,"<>-") -> 0 | C20: =COUNTIFS(sharks!P:P,"CRS",sharks!W:W,"<>-") -> 0 | D20: =COUNTIFS(sharks!P:P,"NS",sharks!AB:AB,"<>-") -> 0
A21: cloacal_swab | B21: =SUMIF(sharks!P:P,"TS",sharks!AC:AC) -> #N/A | C21: =SUMIF(sharks!P:P,"CRS",sharks!AC:AC) -> #N/A | D21: =SUMIF(sharks!P:P,"NS",sharks!AC:AC) -> #N/A
A22: measurements | B22: =COUNTIFS(sharks!P:P,"TS",sharks!R:R,"<>-") -> 0 | C22: =COUNTIFS(sharks!P:P,"CRS",sharks!R:R,"<>-") -> 0 | D22: =COUNTIFS(sharks!P:P,"NS",sharks!R:R,"<>-") -> 0
A25: Shark S10 --> pregnant but no satellite tag
